Workbook
Name Scenario: Drivers!$B$6
Name iPhone_Units_Growth_Active: Drivers!$G$10
Name iPhone_ASP_YoY_Active: Drivers!$G$11
Name iPhone_ASP_Active: Drivers!$G$12
Name Mac_Units_Growth_Active: Drivers!$G$13
Name Mac_ASP_YoY_Active: Drivers!$G$14
Name Mac_ASP_Active: Drivers!$G$15
Name iPad_Units_Growth_Active: Drivers!$G$16
Name iPad_ASP_YoY_Active: Drivers!$G$17
Name iPad_ASP_Active: Drivers!$G$18
Name Wearables_Home_and_Accessories_Units_Growth_Active: Drivers!$G$19
Name Wearables_Home_and_Accessories_ASP_YoY_Active: Drivers!$G$20
Name Wearables_Home_and_Accessories_ASP_Active: Drivers!$G$21
Name Services_InstalledBase_Growth_Active: Drivers!$G$24
Name Services_ARPU_YoY_Active: Drivers!$G$25
Name Services_ARPU_Active: Drivers!$G$26
Name FX_Impact_Active: Drivers!$G$29
Name Mix_Impact_Active: Drivers!$G$30
Name Products_GM_Active: Drivers!$G$33
Name Services_GM_Active: Drivers!$G$34
Name SGA_Pct_Rev_Active: Drivers!$G$37
Name RD_Pct_Rev_Active: Drivers!$G$38
Name DSO_Active: Drivers!$G$41
Name DIO_Active: Drivers!$G$42
Name DPO_Active: Drivers!$G$43
Name CapEx_Pct_Rev_Active: Drivers!$G$46
Name Buyback_Pct_FCF_Active: Drivers!$G$47
Name Dividend_Payout_Active: Drivers!$G$48
Name Tax_Rate_Active: Drivers!$G$49
Name Debt_Roll_Active: Drivers!$G$50

Sheet Read Me
A1: README
A2: Prepared by: Mengru Shi | Status: Portfolio case study | Last updated: August 2026
A3: Independent case study using public information. Not an internal Apple document.
A5: Purpose
A6: Driver-based forecast model for a public-company FP&A case study. The workbook supports variance review, reforecasting, bridge analysis, sensitivity testing, and planning recommendations.
A8: Assumptions
A9: Forecasts are reconstructed from public data and explicit driver assumptions. Scenario outputs are model estimates.
A10: Public data does not include internal shipment, pricing, treasury, regional, installed-base, or management inputs.
A12: How to Navigate
A13: Start with Read Me, then review Drivers for assumptions, IS/BS/CF for forecast mechanics, Forecast Bridge for variance logic, Sensitivity for cases, and Output for dashboard source tables.
A15: Model Structure
A16: History -> source public financial data and historical actuals.
... A38: Review Q3 results before changing the Base case. Validate AI investment and subscription attachment assumptions with later public disclosures.

Sheet Drivers
A1: Apple Inc. -- Driver-Based Rolling Forecast Model: DRIVERS
A2: All Base/Bull/Bear inputs are annual run-rate assumptions used by every downstream IS/BS/CF/Bridge/Sensitivity tab in this workbook (Tasks 12-20).
A3: Downstream formulas must reference the ACTIVE column (never Base/Bull/Bear directly) so the entire model recalculates from the single Scenario switch below.
A4: Historical Reference values are sourced from '02 Historical Financial Database.xlsx' (Annual / Segment Detail tabs) and, where Apple does not disclose a figure (all unit/ASP volumes since FY2018, FX/Mix bridge points, installed base outside two earnings-call data points), from the implied-estimate method documented in data/business_memo_source_notes.md's Revenue Driver Tree section. Every such implied/estimated figure is labeled in the Source/Notes column.
A6: SCENARIO SWITCH (drives every Active column below): | B6: Base | C6: <- choose Base / Bull / Bear here (data-validation dropdown)
A8: Driver | B8: Unit | C8: Historical Reference | D8: Base | E8: Bull | F8: Bear | G8: Active | H8: Source / Notes
A9: SEGMENT REVENUE DRIVERS -- UNITS x ASP (iPhone / Mac / iPad / Wearables)
A10: iPhone -- Units Growth % | B10: % | C10: 0.042 | D10: 0.015 | E10: 0.035 | F10: -0.01 | G10: =INDEX(D10:F10,MATCH($B$6,$D$8:$F$8,0)) -> 0.015 | H10: FY2025 real revenue growth +4.2% (10-K, sourced). Base/Bull/Bear units growth is this agent's judgmental decomposition of revenue growth into units vs. ASP components (row below), reflecting IDC/Counterpoint commentary of roughly flat-to-low-single-digit iPhone unit shipments with revenue growth driven more by Pro/Pro Max mix-shift (ASP) than volume. Labeled as an implied estimate per the FY2018 unit-disclosure caveat.
A11: iPhone -- ASP YoY Change % | B11: % | D11: 0.02 | E11: 0.03 | F11: 0.005 | G11: =INDEX(D11:F11,MATCH($B$6,$D$8:$F$8,0)) -> 0.02 | H11: Judgmental split of the segment's historical revenue growth into a units component (row above) and an ASP/mix component (this row); see Source/Notes method note.
A12: iPhone -- ASP $ (implied) | B12: $/unit | C12: 900 | D12: =$C12*(1+D11) -> 918 | E12: =$C12*(1+E11) -> 927 | F12: =$C12*(1+F11) -> 904.5 | G12: =INDEX(D12:F12,MATCH($B$6,$D$8:$F$8,0)) -> 918 | H12: Implied ASP anchor $900 = midpoint of Business Memo's iPhone ASP benchmark range ($850-950, IDC/Counterpoint-style estimate; Apple has not disclosed iPhone unit shipments since FY2018 -- see Revenue Driver Tree Step 1 caveat). Implied FY2025 units at this anchor = $209,586M / $900 = ~232.9M units (estimate, not disclosed).
A13: Mac -- Units Growth % | B13: % | C13: 0.124 | D13: 0.04 | E13: 0.07 | F13: 0 | G13: =INDEX(D13:F13,MATCH($B$6,$D$8:$F$8,0)) -> 0.04 | H13: FY2025 real revenue growth +12.4% (10-K, sourced; M4 chip refresh cycle), but 5-yr history is highly volatile (+14.2%/-26.9%/+2.1%/+12.4%). Base moderates toward a normalized post-refresh growth rate rather than extrapolating the FY2025 spike, per task guidance. Units/ASP split is this agent's judgmental estimate, not disclosed.
A14: Mac -- ASP YoY Change % | B14: % | D14: 0.02 | E14: 0.03 | F14: 0 | G14: =INDEX(D14:F14,MATCH($B$6,$D$8:$F$8,0)) -> 0.02 | H14: Judgmental split of the segment's historical revenue growth into a units component (row above) and an ASP/mix component (this row); see Source/Notes method note.
A15: Mac -- ASP $ (implied) | B15: $/unit | C15: 1400 | D15: =$C15*(1+D14) -> 1428 | E15: =$C15*(1+E14) -> 1442 | F15: =$C15*(1+F14) -> 1400 | G15: =INDEX(D15:F15,MATCH($B$6,$D$8:$F$8,0)) -> 1428 | H15: Implied ASP anchor $1,400 -- market-research-style MacBook ASP benchmark (Apple does not disclose Mac unit shipments; estimate, analogous method to iPhone). Implied FY2025 units = $33,708M / $1,400 = ~24.1M units (estimate).
A16: iPad -- Units Growth % | B16: % | C16: 0.05 | D16: 0.01 | E16: 0.04 | F16: -0.04 | G16: =INDEX(D16:F16,MATCH($B$6,$D$8:$F$8,0)) -> 0.01 | H16: FY2025 revenue +5.0% (10-K, sourced) followed 3 consecutive down years (-8.1%/-3.4%/-5.7% FY22-24) -- weakest segment historically. Base case is cautious (does not extrapolate the FY2025 rebound); Bear resumes the multi-year decline pattern. Units/ASP split is judgmental, not disclosed.
A17: iPad -- ASP YoY Change % | B17: % | D17: 0.015 | E17: 0.02 | F17: 0 | G17: =INDEX(D17:F17,MATCH($B$6,$D$8:$F$8,0)) -> 0.015 | H17: Judgmental split of the segment's historical revenue growth into a units component (row above) and an ASP/mix component (this row); see Source/Notes method note.
A18: iPad -- ASP $ (implied) | B18: $/unit | C18: 475 | D18: =$C18*(1+D17) -> 482.125 | E18: =$C18*(1+E17) -> 484.5 | F18: =$C18*(1+F17) -> 475 | G18: =INDEX(D18:F18,MATCH($B$6,$D$8:$F$8,0)) -> 482.125 | H18: Implied ASP anchor $475 -- market-research-style iPad ASP benchmark (Apple does not disclose iPad unit shipments; estimate). Implied FY2025 units = $28,023M / $475 = ~59.0M units (estimate).
A19: Wearables, Home and Accessories -- Units Growth % | B19: % | C19: -0.036 | D19: -0.01 | E19: 0.03 | F19: -0.05 | G19: =INDEX(D19:F19,MATCH($B$6,$D$8:$F$8,0)) -> -0.01 | H19: Revenue declined 3 straight years (FY23 -3.4%, FY24 -7.1%, FY25 -3.6%) after FY22's +7.5%. Base assumes stabilization (near-flat blended growth); Bear continues the observed decline trend. Units/ASP split is judgmental, not disclosed.
A20: Wearables, Home and Accessories -- ASP YoY Change % | B20: % | D20: 0.01 | E20: 0.02 | F20: 0 | G20: =INDEX(D20:F20,MATCH($B$6,$D$8:$F$8,0)) -> 0.01 | H20: Judgmental split of the segment's historical revenue growth into a units component (row above) and an ASP/mix component (this row); see Source/Notes method note.
A21: Wearables, Home and Accessories -- ASP $ (implied) | B21: $/unit | C21: 165 | D21: =$C21*(1+D20) -> 166.65 | E21: =$C21*(1+E20) -> 168.3 | F21: =$C21*(1+F20) -> 165 | G21: =INDEX(D21:F21,MATCH($B$6,$D$8:$F$8,0)) -> 166.65 | H21: Implied ASP anchor $165 -- market-research-style blended ASP across AirPods/Watch/Accessories (Apple does not disclose unit shipments; estimate). Implied FY2025 units = $35,686M / $165 = ~216.3M units (estimate).
A23: SERVICES DRIVERS -- INSTALLED BASE x ARPU
A24: Services -- Installed Base Growth % | B24: % | C24: 0.0817 | D24: 0.075 | E24: 0.09 | F24: 0.06 | G24: =INDEX(D24:F24,MATCH($B$6,$D$8:$F$8,0)) -> 0.075 | H24: Historical Reference 8.17% = CAGR implied by Apple management's two public disclosures: >2.0B active devices (Jan 2023 earnings call) to >2.35B active devices (Jan 2025 earnings call) -- (2.35/2.00)^(1/2)-1. Not a 10-K disclosure (10-K contains no installed-base figure at all, per Business Memo notes); sourced from Apple management's public earnings-call commentary, per the Installed Base section's recommendation.
A25: Services -- ARPU YoY Change % | B25: % | D25: 0.05 | E25: 0.07 | F25: 0.03 | G25: =INDEX(D25:F25,MATCH($B$6,$D$8:$F$8,0)) -> 0.05 | H25: Implied historical ARPU growth ~4-6%/yr, derived from Services revenue growth (14.2%/9.1%/12.9%/13.5% FY22-25, 10-K sourced) less installed-base growth (row above). ARPU itself is not an Apple-disclosed metric -- it is computed as Services Revenue / Installed Base, both components estimated/sourced as noted.
A26: Services -- ARPU $ (implied, annual) | B26: $/device/yr | C26: 46.45 | D26: =$C26*(1+D25) -> 48.7725 | E26: =$C26*(1+E25) -> 49.7015 | F26: =$C26*(1+F25) -> 47.8435 | G26: =INDEX(D26:F26,MATCH($B$6,$D$8:$F$8,0)) -> 48.7725 | H26: Historical Reference $46.45 = FY2025 Services net sales $109,158M / 2.35B installed base (both sourced per notes above). Implied estimate, not an Apple-disclosed figure.
A28: OVERLAY ADJUSTMENTS -- FX & MIX (applied on top of Units x ASP / Installed Base x ARPU, per Revenue Driver Tree Step 3)
A29: FX Impact on Revenue % | B29: % | D29: 0 | E29: 0.01 | F29: -0.015 | G29: =INDEX(D29:F29,MATCH($B$6,$D$8:$F$8,0)) -> 0 | H29: No FX revenue bridge is disclosed in the FY2023-FY2025 10-Ks captured in the Historical Database / source notes (the MD&A tables extracted do not quantify an FX point-impact). Base case is therefore set to a neutral 0% (no assumed FX tailwind/headwind). Bull/Bear illustrate a directionally typical swing for a USD-weakens / USD-strengthens scenario and are explicitly labeled as this agent's assumption, not a sourced figure.
A30: Mix Impact on Revenue % | B30: % | D30: 0 | E30: 0.005 | F30: -0.005 | G30: =INDEX(D30:F30,MATCH($B$6,$D$8:$F$8,0)) -> 0 | H30: Residual product/regional/channel mix effect not already captured by the explicit segment ASP and Services ARPU trajectories above. No disclosed mix-bridge figure exists; Base is neutral (0%), Bull/Bear are this agent's illustrative assumption, explicitly labeled as such, kept separate from ASP/ARPU per the Revenue Driver Tree's Step 3 instruction (FX and Mix must not be folded into ASP).
A32: GROSS MARGIN DRIVERS (Products and Services split -- never a single blended GM%)
A33: Products Gross Margin % | B33: % | C33: 0.368 | D33: 0.37 | E33: 0.38 | F33: 0.355 | G33: =INDEX(D33:F33,MATCH($B$6,$D$8:$F$8,0)) -> 0.37 | H33: Historical Reference 36.8% = FY2025 actual (10-K, sourced). 5-yr avg 36.4%, 3-yr avg 36.8% -- stable range. Base holds near the recent average; Bear reflects tariff cost pressure (FY2025 MD&A: 'Products gross margin percentage decreased ... primarily due to a different mix of products and tariff costs').
A34: Services Gross Margin % | B34: % | C34: 0.754 | D34: 0.755 | E34: 0.77 | F34: 0.735 | G34: =INDEX(D34:F34,MATCH($B$6,$D$8:$F$8,0)) -> 0.755 | H34: Historical Reference 75.4% = FY2025 actual (10-K, sourced). 5-yr trend is a steady climb (69.7/71.7/70.8/73.9/75.4), 3-yr avg 73.4%. Base assumes continued modest expansion consistent with the trend; Bear reverts toward the 3-yr average.
A36: OPERATING EXPENSE DRIVERS (% of total revenue)
A37: SG&A (% of Revenue) | B37: % | C37: 0.0663 | D37: 0.066 | E37: 0.062 | F37: 0.072 | G37: =INDEX(D37:F37,MATCH($B$6,$D$8:$F$8,0)) -> 0.066 | H37: Historical Reference 6.63% = FY2025 actual (10-K, sourced: SG&A $27,601M / Revenue $416,161M). 5-yr trend 6.01/6.36/6.50/6.67/6.63% -- rising then plateauing. Bull = LOWER cost ratio (operating use); Bear = higher cost ratio (cost inflation).
A38: R&D (% of Revenue) | B38: % | C38: 0.083 | D38: 0.083 | E38: 0.078 | F38: 0.09 | G38: =INDEX(D38:F38,MATCH($B$6,$D$8:$F$8,0)) -> 0.083 | H38: Historical Reference 8.30% = FY2025 actual (10-K, sourced: R&D $34,550M / Revenue $416,161M). 5-yr trend is a steady climb (5.99/6.66/7.80/8.02/8.30%), consistent with the Business Memo's AI Strategy commentary on rising R&D intensity. Bull = LOWER cost ratio (revenue outgrows R&D spend); Bear = continued heavy AI investment without proportional revenue growth.
A40: WORKING CAPITAL DRIVERS (days; AR via DSO, Inventory via DIO, AP via DPO)
A41: Days Sales Outstanding (DSO) | B41: days | C41: 29.3 | D41: 33 | E41: 29 | F41: 37 | G41: =INDEX(D41:F41,MATCH($B$6,$D$8:$F$8,0)) -> 33 | H41: Historical Reference 29.3 days = 5-yr average of (AR / Total Revenue x 365) computed from the Historical Database Annual tab: 26.2/26.1/28.1/31.2/34.9 days FY21-25 -- a clear, steady rising trend (slower collections). Base (33.0) sits near the FY2025 actual (34.9) with slight mean-reversion; Bull = LOWER DSO (faster collection, favorable); Bear = continued deterioration along the observed trend.
A42: Days Inventory Outstanding (DIO) | B42: days | C42: 10.4 | D42: 10 | E42: 8 | F42: 13 | G42: =INDEX(D42:F42,MATCH($B$6,$D$8:$F$8,0)) -> 10 | H42: Historical Reference 10.4 days = 5-yr average of (Inventory / implied COGS x 365) computed from the Historical Database Annual tab (implied COGS = Total Revenue - Total Gross Margin): 11.3/8.1/10.8/12.6/9.4 days FY21-25 -- volatile, no clear trend. Bull = LOWER DIO (tighter inventory management, favorable); Bear = looser inventory control / supply-chain slippage.
A43: Days Payable Outstanding (DPO) | B43: days | C43: 108.1 | D43: 115 | E43: 122 | F43: 105 | G43: =INDEX(D43:F43,MATCH($B$6,$D$8:$F$8,0)) -> 115 | H43: Historical Reference 108.1 days = 5-yr average of (AP / implied COGS x 365) computed from the Historical Database Annual tab: 93.9/104.7/106.7/119.7/115.4 days FY21-25 -- a clear rising trend, leveling near 115-120 in FY24-25. Base sits near the recent level; Bull = HIGHER DPO (extended payables, favorable for cash conversion); Bear = payables tighten (less favorable).
A45: CAPITAL STRUCTURE DRIVERS
A46: CapEx (% of Revenue) | B46: % | C46: 0.0306 | D46: 0.03 | E46: 0.026 | F46: 0.038 | G46: =INDEX(D46:F46,MATCH($B$6,$D$8:$F$8,0)) -> 0.03 | H46: Historical Reference 3.06% = FY2025 actual (10-K, sourced: CapEx $12,715M / Revenue $416,161M). 5-yr trend 3.03/2.72/2.86/2.42/3.06% -- FY2025 spike reflects AI infrastructure buildout. Base continues at the elevated FY2025 level; Bull = LOWER CapEx ratio (capital efficiency, more FCF); Bear = further accelerated AI infra spend.
A47: Buyback ($ as % of Trailing FCF) | B47: % | C47: 0.918 | D47: 0.9 | E47: 1 | F47: 0.75 | G47: =INDEX(D47:F47,MATCH($B$6,$D$8:$F$8,0)) -> 0.9 | H47: Historical Reference 91.8% = FY2025 actual (10-K, sourced: Repurchases $90,711M / FCF $98,767M, where FCF = OCF $111,482M - CapEx $12,715M per the Business Memo's Free Cash Flow KPI formula). 5-yr trend 92.5/80.2/77.9/87.3/91.8%. Bull = MORE aggressive capital return (higher %); Bear = more conservative / capital preservation.
A48: Dividend Payout (% of Net Income) | B48: % | C48: 0.1377 | D48: 0.15 | E48: 0.16 | F48: 0.14 | G48: =INDEX(D48:F48,MATCH($B$6,$D$8:$F$8,0)) -> 0.15 | H48: Historical Reference 13.77% = FY2025 actual (10-K, sourced: Dividends paid $15,421M / Net income $112,010M). 5-yr trend 15.28/14.87/15.49/16.25/13.77% -- fairly stable ~14-16% band (FY2025's dip driven by the NI spike, not a payout cut). Base sits mid-band; Bull = higher payout (dividend growth); Bear = lower payout.
...

Sheet IS
A1: Apple Inc. -- Driver-Based Rolling Forecast Model: INCOME STATEMENT (IS)
A2: Historical actuals (FY24 Q1 - FY26 Q2, columns B:K) are pulled directly, unmodified, from '02 Historical Financial Database.xlsx' Quarterly tab -- real disclosed/XBRL-derived figures, not re-derived. Segment/product-line revenue is not available at quarterly grain in that source (see Segment Detail tab note), so historical columns show consolidated IS lines only.
A3: FY2026 Approved AOP (columns L:P) is the first vintage in the rolling-forecast chain (Project Spec): built entirely from real Excel formulas referencing the Drivers tab's Active column (Base/Bull/Bear switch at Drivers!B6) applied to FY2025 actual segment/Services revenue anchors, split into quarters via FY2024-FY2025 average seasonality weights (rows 8-13). Simplifications: Other income/(expense) is treated as immaterial (Tax_Rate_Active applied directly to Operating Income, not a separately-driven pretax line); diluted share count is held flat at the FY26 Q2 actual implied count (buyback-driven share-count reduction is a Balance Sheet/Cash Flow mechanic for a later task, not modeled in this IS tab). Later tasks add further vintage column blocks (Q1 Update, Q3 Reforecast, FY2027 AOP) to the right of this tab -- this FY2026 Approved AOP block is never overwritten.
B5: HISTORICAL ACTUALS -- Source: 02 Historical Financial Database.xlsx, Quarterly tab (real values, not re-derived) | L5: FY2026 Approved AOP -- first rolling-forecast vintage (Drivers tab Active column; Base/Bull/Bear scenario switch at Drivers!B6) | Q5: Q1 FY2026 ACTUAL vs. APPROVED AOP VARIANCE -- Actual = mirror of historical col J (real data); Variance = Actual - Approved AOP Q1 (col L) | T5: Q1 FORECAST UPDATE -- second rolling-forecast vintage (Q1 FY2026 actual reported; Q2-Q4 FY2026 reforecast using the Drivers tab Active column PLUS the Q1-actual driver adjustments in rows 63-78 below, in place of reverting to the original AOP assumptions where the Q1 variance was material) | X5: NOTES | Y5: Q2 FY2026 ACTUAL vs. Q1 FORECAST UPDATE VARIANCE -- Actual = mirror of historical col K (real data); Variance = Actual - Q1 Forecast Update's own Q2 column (T) | AB5: Q3 REFORECAST -- third rolling-forecast vintage, and the CURRENT / LIVE forecast in this project's story (Q1 and Q2 FY2026 are now both real actuals; Q3-Q4 reforecast using the Q1 Forecast Update's own Annual Build PLUS the Q2-actual driver adjustments in rows 84-99 below, in place of reverting to the Q1 Forecast Update's own assumptions where the Q2 variance was material) | AE5: NOTES | AF5: FY2027 AOP -- fifth and FINAL rolling-forecast vintage: next year's Annual Operating Plan, built off the Q3 Reforecast's Q4 FY2026 EXIT run-rate (col AC de-seasonalized by dividing by the Q4 weight, row 12 col E -- NOT a naive x4, and NOT the Q3 Reforecast's FY26 Total), grown one more year via the Drivers tab's Active assumptions (Base/Bull/Bear switch at Drivers!B6). Fresh forward plan -- no Driver Adjustment Log (see row 125). | AK5: NOTES
A6: Line Item | B6: FY24 Q1 | C6: FY24 Q2 | D6: FY24 Q3 | E6: FY24 Q4 | F6: FY25 Q1 | G6: FY25 Q2 | H6: FY25 Q3 | I6: FY25 Q4 | J6: FY26 Q1 (Actual) | K6: FY26 Q2 (Actual) | L6: Q1 -- FY2026 Approved AOP | M6: Q2 -- FY2026 Approved AOP | N6: Q3 -- FY2026 Approved AOP | O6: Q4 -- FY2026 Approved AOP | P6: FY26 Total -- FY2026 Approved AOP | Q6: Q1 FY2026 Actual | R6: Q1 vs AOP Variance ($) | S6: Q1 vs AOP Variance (%) | T6: Q2 -- Q1 Forecast Update | U6: Q3 -- Q1 Forecast Update | V6: Q4 -- Q1 Forecast Update | W6: FY26 Total -- Q1 Forecast Update | X6: Notes -- Q1 Forecast Update Rationale | Y6: Q2 FY2026 Actual | Z6: Q2 vs Q1 FU Variance ($) | AA6: Q2 vs Q1 FU Variance (%) | AB6: Q3 -- Q3 Reforecast | AC6: Q4 -- Q3 Reforecast | AD6: FY26 Total -- Q3 Reforecast | AE6: Notes -- Q3 Reforecast Rationale | AF6: Q1 -- FY2027 AOP | AG6: Q2 -- FY2027 AOP | AH6: Q3 -- FY2027 AOP | AI6: Q4 -- FY2027 AOP | AJ6: FY27 Total -- FY2027 AOP | AK6: Notes -- FY2027 AOP Rationale
A8: SEASONALITY WEIGHTS -- average of FY2024 & FY2025 quarterly Net Sales as % of that FY's total (columns B:E in THIS block only = Q1..Q4, not fiscal years)
A9: Quarter | B9: Q1 | C9: Q2 | D9: Q3 | E9: Q4
A10: FY2024 Net Sales % of FY2024 Total | B10: =B41/SUM($B$41:$E$41) -> 0.30579104 | C10: =C41/SUM($B$41:$E$41) -> 0.23208408 | D10: =D41/SUM($B$41:$E$41) -> 0.21935888 | E10: =E41/SUM($B$41:$E$41) -> 0.24276599
A11: FY2025 Net Sales % of FY2025 Total | B11: =F41/SUM($F$41:$I$41) -> 0.29868248 | C11: =G41/SUM($F$41:$I$41) -> 0.22913968 | D11: =H41/SUM($F$41:$I$41) -> 0.22596063 | E11: =I41/SUM($F$41:$I$41) -> 0.24621721
A12: Average Seasonality Weight (applied to AOP annual $) | B12: =AVERAGE(B10,B11) -> 0.30223676 | C12: =AVERAGE(C10,C11) -> 0.23061188 | D12: =AVERAGE(D10,D11) -> 0.22265975 | E12: =AVERAGE(E10,E11) -> 0.2444916
A13: Check: weights sum to 100% | B13: =SUM(B12:E12) -> 1
A15: FY2026 APPROVED AOP -- ANNUAL BUILD (helper: Drivers Active column x FY2025 actual anchors -> full-year AOP revenue, before the seasonality quarterly split above)
A16: iPhone: FY2025 Actual Revenue anchor ($M) | B16: 209586 | C16: Real FY2025 actual, sourced from 02 Historical Financial Database.xlsx Segment Detail tab (10-K disclosed).
A17: iPhone: Implied FY2025 Units (M) | B17: =B16/Drivers!$C$12 -> 232.87333 | C17: FY2025 anchor revenue divided by Drivers!C12 (Historical Reference ASP/ARPU $; not scenario-dependent).
A18: iPhone: FY2026 AOP Annual Revenue ($M) | B18: =B17*(1+iPhone_Units_Growth_Active)*iPhone_ASP_Active*(1+FX_Impact_Active)*(1+Mix_Impact_Active) -> 216984.39 | C18: Implied units/base x (1+iPhone_Units_Growth_Active) x iPhone_ASP_Active x (1+FX_Impact_Active) x (1+Mix_Impact_Active).
A19: Mac: FY2025 Actual Revenue anchor ($M) | B19: 33708 | C19: Real FY2025 actual, sourced from 02 Historical Financial Database.xlsx Segment Detail tab (10-K disclosed).
A20: Mac: Implied FY2025 Units (M) | B20: =B19/Drivers!$C$15 -> 24.077143 | C20: FY2025 anchor revenue divided by Drivers!C15 (Historical Reference ASP/ARPU $; not scenario-dependent).
A21: Mac: FY2026 AOP Annual Revenue ($M) | B21: =B20*(1+Mac_Units_Growth_Active)*Mac_ASP_Active*(1+FX_Impact_Active)*(1+Mix_Impact_Active) -> 35757.446 | C21: Implied units/base x (1+Mac_Units_Growth_Active) x Mac_ASP_Active x (1+FX_Impact_Active) x (1+Mix_Impact_Active).
A22: iPad: FY2025 Actual Revenue anchor ($M) | B22: 28023 | C22: Real FY2025 actual, sourced from 02 Historical Financial Database.xlsx Segment Detail tab (10-K disclosed).
A23: iPad: Implied FY2025 Units (M) | B23: =B22/Drivers!$C$18 -> 58.995789 | C23: FY2025 anchor revenue divided by Drivers!C18 (Historical Reference ASP/ARPU $; not scenario-dependent).
A24: iPad: FY2026 AOP Annual Revenue ($M) | B24: =B23*(1+iPad_Units_Growth_Active)*iPad_ASP_Active*(1+FX_Impact_Active)*(1+Mix_Impact_Active) -> 28727.778 | C24: Implied units/base x (1+iPad_Units_Growth_Active) x iPad_ASP_Active x (1+FX_Impact_Active) x (1+Mix_Impact_Active).
A25: Wearables, Home and Accessories: FY2025 Actual Revenue anchor ($M) | B25: 35686 | C25: Real FY2025 actual, sourced from 02 Historical Financial Database.xlsx Segment Detail tab (10-K disclosed).
A26: Wearables, Home and Accessories: Implied FY2025 Units (M) | B26: =B25/Drivers!$C$21 -> 216.27879 | C26: FY2025 anchor revenue divided by Drivers!C21 (Historical Reference ASP/ARPU $; not scenario-dependent).
A27: Wearables, Home and Accessories: FY2026 AOP Annual Revenue ($M) | B27: =B26*(1+Wearables_Home_and_Accessories_Units_Growth_Active)*Wearables_Home_and_Accessories_ASP_Active*(1+FX_Impact_Active)*(1+Mix_Impact_Active) -> 35682.431 | C27: Implied units/base x (1+Wearables_Home_and_Accessories_Units_Growth_Active) x Wearables_Home_and_Accessories_ASP_Active x (1+FX_Impact_Active) x (1+Mix_Impact_Active).
A28: Services: FY2025 Actual Revenue anchor ($M) | B28: 109158 | C28: Real FY2025 actual, sourced from 02 Historical Financial Database.xlsx Segment Detail tab (10-K disclosed).
A29: Services: Implied FY2025 Installed Base (M devices) | B29: =B28/Drivers!$C$26 -> 2350.0108 | C29: FY2025 anchor revenue divided by Drivers!C26 (Historical Reference ASP/ARPU $; not scenario-dependent).
A30: Services: FY2026 AOP Annual Revenue ($M) | B30: =B29*(1+Services_InstalledBase_Growth_Active)*Services_ARPU_Active*(1+FX_Impact_Active)*(1+Mix_Impact_Active) -> 123212.09 | C30: Implied units/base x (1+Services_InstalledBase_Growth_Active) x Services_ARPU_Active x (1+FX_Impact_Active) x (1+Mix_Impact_Active).
A31: Total FY2026 AOP Annual Revenue ($M) | B31: =B18+B21+B24+B27+B30 -> 440364.13
A33: INCOME STATEMENT
A34: =A6 -> Line Item | B34: =B6 -> FY24 Q1 | C34: =C6 -> FY24 Q2 | D34: =D6 -> FY24 Q3 | E34: =E6 -> FY24 Q4 | F34: =F6 -> FY25 Q1 | G34: =G6 -> FY25 Q2 | H34: =H6 -> FY25 Q3 | ... AK34: =AK6 -> Notes -- FY2027 AOP Rationale
A35: iPhone Revenue ($M) | B35: n/a | C35: n/a | D35: n/a | E35: n/a | F35: n/a | G35: n/a | H35: n/a | I35: n/a | J35: n/a | K35: n/a | L35: =$B$18*$B$12 -> 65580.658 | M35: =$B$18*$C$12 -> 50039.178 | N35: =$B$18*$D$12 -> 48313.69 | O35: =$B$18*$E$12 -> 53050.86 | P35: =SUM(L35:O35) -> 216984.39 | Q35: =J35 -> n/a | R35: n/a | S35: n/a | T35: =$B$73*$C$12 -> 51250.69 | U35: =$B$73*$D$12 -> 49483.425 | V35: =$B$73*$E$12 -> 54335.288 | W35: =SUM(Q35,T35:V35) -> 155069.4 | Y35: =K35 -> n/a | Z35: n/a | AA35: n/a | AB35: =$B$94*$D$12 -> 50270.294 | AC35: =$B$94*$E$12 -> 55199.31 | AD35: =SUM(Q35,Y35,AB35:AC35) -> 105469.6 | AF35: =$B$109*$B$12 -> 69260.087 | AG35: =$B$109*$C$12 -> 52846.646 | AH35: =$B$109*$D$12 -> 51024.349 | AI35: =$B$109*$E$12 -> 56027.3 | AJ35: =SUM(AF35:AI35) -> 229158.38
A36: Mac Revenue ($M) | B36: n/a | C36: n/a | D36: n/a | E36: n/a | F36: n/a | G36: n/a | H36: n/a | I36: n/a | J36: n/a | K36: n/a | L36: =$B$21*$B$12 -> 10807.215 | M36: =$B$21*$C$12 -> 8246.0921 | N36: =$B$21*$D$12 -> 7961.7442 | O36: =$B$21*$E$12 -> 8742.3953 | P36: =SUM(L36:O36) -> 35757.446 | Q36: =J36 -> n/a | R36: n/a | S36: n/a | T36: =$B$74*$C$12 -> 8445.7404 | U36: =$B$74*$D$12 -> 8154.508 | V36: =$B$74*$E$12 -> 8954.0597 | W36: =SUM(Q36,T36:V36) -> 25554.308 | Y36: =K36 -> n/a | Z36: n/a | AA36: n/a | AB36: =$B$95*$D$12 -> 8284.1784 | AC36: =$B$95*$E$12 -> 9096.4442 | AD36: =SUM(Q36,Y36,AB36:AC36) -> 17380.623 | AF36: =$B$112*$B$12 -> 11694.68 | AG36: =$B$112*$C$12 -> 8923.2434 | AH36: =$B$112*$D$12 -> 8615.5455 | AI36: =$B$112*$E$12 -> 9460.302 | AJ36: =SUM(AF36:AI36) -> 38693.771
A37: iPad Revenue ($M) | B37: n/a | C37: n/a | D37: n/a | E37: n/a | F37: n/a | G37: n/a | H37: n/a | I37: n/a | J37: n/a | K37: n/a | L37: =$B$24*$B$12 -> 8682.5907 | M37: =$B$24*$C$12 -> 6624.9671 | N37: =$B$24*$D$12 -> 6396.5201 | O37: =$B$24*$E$12 -> 7023.7005 | P37: =SUM(L37:O37) -> 28727.778 | Q37: =J37 -> n/a | R37: n/a | S37: n/a | T37: =$B$75*$C$12 -> 6785.3659 | U37: =$B$75*$D$12 -> 6551.3879 | V37: =$B$75*$E$12 -> 7193.7532 | W37: =SUM(Q37,T37:V37) -> 20530.507 | Y37: =K37 -> n/a | Z37: n/a | AA37: n/a | AB37: =$B$96*$D$12 -> 6655.5659 | AC37: =$B$96*$E$12 -> 7308.1459 | AD37: =SUM(Q37,Y37,AB37:AC37) -> 13963.712 | AF37: =$B$115*$B$12 -> 9124.5599 | AG37: =$B$115*$C$12 -> 6962.1972 | AH37: =$B$115*$D$12 -> 6722.1216 | AI37: =$B$115*$E$12 -> 7381.2273 | AJ37: =SUM(AF37:AI37) -> 30190.106
A38: Wearables, Home and Accessories Revenue ($M) | B38: n/a | C38: n/a | D38: n/a | E38: n/a | F38: n/a | G38: n/a | H38: n/a | I38: n/a | J38: n/a | K38: n/a | L38: =$B$27*$B$12 -> 10784.543 | M38: =$B$27*$C$12 -> 8228.7927 | N38: =$B$27*$D$12 -> 7945.0414 | O38: =$B$27*$E$12 -> 8724.0548 | P38: =SUM(L38:O38) -> 35682.431 | Q38: =J38 -> n/a | R38: n/a | S38: n/a | T38: =$B$76*$C$12 -> 8428.0222 | U38: =$B$76*$D$12 -> 8137.4008 | V38: =$B$76*$E$12 -> 8935.2751 | W38: =SUM(Q38,T38:V38) -> 25500.698 | Y38: =K38 -> n/a | Z38: n/a | AA38: n/a | AB38: =$B$97*$D$12 -> 8266.7991 | AC38: =$B$97*$E$12 -> 9077.361 | AD38: =SUM(Q38,Y38,AB38:AC38) -> 17344.16 | AF38: =$B$118*$B$12 -> 11109.081 | AG38: =$B$118*$C$12 -> 8476.4214 | AH38: =$B$118*$D$12 -> 8184.1311 | AI38: =$B$118*$E$12 -> 8986.5873 | AJ38: =SUM(AF38:AI38) -> 36756.221
A39: Products Revenue Subtotal ($M) | B39: n/a | C39: n/a | D39: n/a | E39: n/a | F39: n/a | G39: n/a | H39: n/a | I39: n/a | J39: n/a | K39: n/a | L39: =SUM(L35:L38) -> 95855.006 | M39: =SUM(M35:M38) -> 73139.03 | N39: =SUM(N35:N38) -> 70616.995 | O39: =SUM(O35:O38) -> 77541.011 | P39: =SUM(P35:P38) -> 317152.04 | Q39: =J39 -> n/a | R39: n/a | S39: n/a | T39: =SUM(T35:T38) -> 74909.818 | U39: =SUM(U35:U38) -> 72326.722 | V39: =SUM(V35:V38) -> 79418.376 | W39: =SUM(Q39,T39:V39) -> 226654.92 | Y39: =K39 -> n/a | Z39: n/a | AA39: n/a | AB39: =SUM(AB35:AB38) -> 73476.838 | AC39: =SUM(AC35:AC38) -> 80681.261 | AD39: =SUM(Q39,Y39,AB39:AC39) -> 154158.1 | AF39: =SUM(AF35:AF38) -> 101188.41 | AG39: =SUM(AG35:AG38) -> 77208.508 | AH39: =SUM(AH35:AH38) -> 74546.147 | AI39: =SUM(AI35:AI38) -> 81855.416 | AJ39: =SUM(AJ35:AJ38) -> 334798.48
A40: Services Revenue ($M) | B40: n/a | C40: n/a | D40: n/a | E40: n/a | F40: n/a | G40: n/a | H40: n/a | I40: n/a | J40: n/a | K40: n/a | L40: =$B$30*$B$12 -> 37239.224 | M40: =$B$30*$C$12 -> 28414.173 | N40: =$B$30*$D$12 -> 27434.374 | O40: =$B$30*$E$12 -> 30124.322 | P40: =SUM(L40:O40) -> 123212.09 | Q40: =J40 -> n/a | R40: n/a | S40: n/a | T40: =$B$77*$C$12 -> 29102.116 | U40: =$B$77*$D$12 -> 28098.595 | V40: =$B$77*$E$12 -> 30853.67 | W40: =SUM(Q40,T40:V40) -> 88054.38 | Y40: =K40 -> n/a | Z40: n/a | AA40: n/a | AB40: =$B$98*$D$12 -> 28545.41 | AC40: =$B$98*$E$12 -> 31344.294 | AD40: =SUM(Q40,Y40,AB40:AC40) -> 59889.704 | AF40: =$B$121*$B$12 -> 41653.385 | AG40: =$B$121*$C$12 -> 31782.255 | AH40: =$B$121*$D$12 -> 30686.315 | AI40: =$B$121*$E$12 -> 33695.117 | AJ40: =SUM(AF40:AI40) -> 137817.07
A41: Net sales / Total Revenue ($M) | B41: 119575 | C41: 90753 | D41: 85777 | E41: 94930 | F41: 124300 | G41: 95359 | H41: 94036 | I41: 102466 | J41: 143756 | K41: 111184 | L41: =L39+L40 -> 133094.23 | M41: =M39+M40 -> 101553.2 | N41: =N39+N40 -> 98051.37 | O41: =O39+O40 -> 107665.33 | P41: =P39+P40 -> 440364.13 | Q41: =J41 -> 143756 | R41: =Q41-L41 -> 10661.77 | S41: =R41/ABS(L41) -> 0.08010693 | T41: =T39+T40 -> 104011.93 | U41: =U39+U40 -> 100425.32 | V41: =V39+V40 -> 110272.05 | W41: =SUM(Q41,T41:V41) -> 458465.3 | X41: Q2-Q4 FU revenue is built off each segment's AOP annual revenue grossed up by the Q1 blended revenue-growth-surprise factor (+~8.0%; see Driver Adjustment Log row 65 and Annual Build rows 73-78) -- carried forward because Q1 actual net sales materially beat the AOP Q1 assumption, rather than reverting to the original AOP units/ASP growth path for the rest of the year. | Y41: =K41 -> 111184 | Z41: =Y41-T41 -> 7172.0663 | AA41: =Z41/ABS(T41) -> 0.068954263 | AB41: =AB39+AB40 -> 102022.25 | AC41: =AC39+AC40 -> 112025.56 | AD41: =SUM(Q41,Y41,AB41:AC41) -> 468987.8 | AE41: Q3-Q4 Reforecast revenue is built off each segment's Q1 Forecast Update annual revenue grossed up by the Q2 blended revenue-growth-surprise factor (+~1.6% of Q1 FU Annual Total; see Driver Adjustment Log row 86 and Annual Build rows 94-98) -- carried forward because Q2 actual net sales materially beat the Q1 Forecast Update's own Q2 assumption, rather than reverting to the Q1 FU's unmodified Q3-Q4 path. | AF41: =AF39+AF40 -> 142841.79 | AG41: =AG39+AG40 -> 108990.76 | AH41: =AH39+AH40 -> 105232.46 | AI41: =AI39+AI40 -> 115550.53 | AJ41: =AJ39+AJ40 -> 472615.55 | AK41: FY2027 AOP revenue is built off each segment's FY2026 Exit Run-Rate Annualized Revenue (Q3 Reforecast's Q4 FY2026 revenue, col AC, de-seasonalized by dividing by the Q4 weight, row 12 col E -- rows 107-121), NOT a naive x4 (which would understate the anchor by assuming an even 25% quarterly share) and NOT the Q3 Reforecast's FY26 Total (which blends in the already-reported Q1/Q2 actuals), then grown one more year via Drivers Active Units/ASP/InstalledBase/ARPU/FX/Mix -- same formula shape as Task 12's original AOP build, one year later.
A43: Cost of sales ($M) | B43: 64720 | C43: 48482 | D43: 46099 | E43: 51051 | F43: 66025 | G43: 50492 | H43: 50318 | I43: 54125 | J43: 74525 | K43: 56403 | L43: =L41-L44 -> 69512.264 | M43: =M41-M44 -> 53039.061 | N43: =N41-N44 -> 51210.129 | O43: =O41-O44 -> 56231.295 | P43: =SUM(L43:O43) -> 229992.75 | Q43: =J43 -> 74525 | R43: =Q43-L43 -> 5012.7364 | S43: =R43/ABS(L43) -> 0.072112978 | T43: =T41-T44 -> 54323.204 | U43: =U41-U44 -> 52449.99 | V43: =V41-V44 -> 57592.726 | W43: =SUM(Q43,T43:V43) -> 238890.92 | Y43: =K43 -> 56403 | Z43: =Y43-T43 -> 2079.7963 | AA43: =Z43/ABS(T43) -> 0.038285597 | AB43: =AB41-AB44 -> 51755.296 | AC43: =AC41-AC44 -> 56829.916 | AD43: =SUM(Q43,Y43,AB43:AC43) -> 239513.21 | AF43: =AF41-AF44 -> 73953.777 | AG43: =AG41-AG44 -> 56428.013 | AH43: =AH41-AH44 -> 54482.22 | AI43: =AI41-AI44 -> 59824.216 | AJ43: =SUM(AF43:AI43) -> 244688.22
A44: Gross margin ($M) | B44: 54855 | C44: 42271 | D44: 39678 | E44: 43879 | F44: 58275 | G44: 44867 | H44: 43718 | I44: 48341 | J44: 69231 | K44: 54781 | L44: =L39*Products_GM_Active+L40*Services_GM_Active -> 63581.966 | M44: =M39*Products_GM_Active+M40*Services_GM_Active -> 48514.142 | N44: =N39*Products_GM_Active+N40*Services_GM_Active -> 46841.241 | O44: =O39*Products_GM_Active+O40*Services_GM_Active -> 51434.037 | P44: =SUM(L44:O44) -> 210371.39 | Q44: =J44 -> 69231 | R44: =Q44-L44 -> 5649.0338 | S44: =R44/ABS(L44) -> 0.088846478 | T44: =T39*Products_GM_Active+T40*Services_GM_Active -> 49688.73 | U44: =U39*Products_GM_Active+U40*Services_GM_Active -> 47975.326 | V44: =V39*Products_GM_Active+V40*Services_GM_Active -> 52679.32 | W44: =SUM(Q44,T44:V44) -> 219574.38 | Y44: =K44 -> 54781 | Z44: =Y44-T44 -> 5092.27 | AA44: =Z44/ABS(T44) -> 0.1024834 | AB44: =AB41*$G$87 -> 50266.951 | AC44: =AC41*$G$87 -> 55195.639 | AD44: =SUM(Q44,Y44,AB44:AC44) -> 229474.59 | AF44: =AF39*Products_GM_Active+AF40*Services_GM_Active -> 68888.017 | AG44: =AG39*Products_GM_Active+AG40*Services_GM_Active -> 52562.75 | AH44: =AH39*Products_GM_Active+AH40*Services_GM_Active -> 50750.242 | AI44: =AI39*Products_GM_Active+AI40*Services_GM_Active -> 55726.317 | AJ44: =SUM(AF44:AI44) -> 227927.33
A45: Gross margin % | B45: =B44/B41 -> 0.45874974 | C45: =C44/C41 -> 0.46578075 | D45: =D44/D41 -> 0.46257155 | E45: =E44/E41 -> 0.4622248 | F45: =F44/F41 -> 0.46882542 | G45: =G44/G41 -> 0.47050619 | H45: =H44/H41 -> 0.46490706 | I45: =I44/I41 -> 0.471776 | ... P45: =P44/P41 -> 0.47772143 | Q45: =J45 -> 0.48158686 | R45: =Q45-L45 -> 0.0038654225 | S45: n/a (pp diff shown at left) | T45: =T44/T41 -> 0.47772143 | U45: =U44/U41 -> 0.47772143 | V45: =V44/V41 -> 0.47772143 | W45: =SUM(Q45,T45:V45) -> 1.9147512 | X45: Unchanged from AOP -- Q1 GM% variance was immaterial (+0.8% relative, below the 3% threshold; row 66). Q2-Q4 FU still uses Products_GM_Active / Services_GM_Active exactly as the AOP did. | Y45: =K45 -> 0.49270579 | Z45: =Y45-T45 -> 0.014984352 | AA45: n/a (pp diff shown at left) | AB45: =AB44/AB41 -> 0.49270579 | AC45: =AC44/AC41 -> 0.49270579 | AD45: =SUM(Q45,Y45,AB45:AC45) -> 1.9597042 | AE45: Q3-Q4 Reforecast GM% uses the Q2 actual blended GM% (~49.3%), not the Q1 Forecast Update's own Q2 assumption (~47.8%, itself Products_GM_Active/Services_GM_Active-based) -- a +3.1% relative variance, just above the 3% threshold (row 87); a borderline call, flagged explicitly in the log rationale. | AF45: =AF44/AF41 -> 0.48226794 | AG45: =AG44/AG41 -> 0.48226794 | AH45: =AH44/AH41 -> 0.48226794 | AI45: =AI44/AI41 -> 0.48226794 | AJ45: =AJ44/AJ41 -> 0.48226794 | AK45: Uses Drivers!Products_GM_Active / Services_GM_Active directly (NOT the Q3 Reforecast's Q2-actual-pinned GM% override, row 87) -- FY2027 is a fresh forward plan, not a reforecast of FY2026 execution reality.
...

Sheet BS
A1: Apple Inc. -- Driver-Based Rolling Forecast Model: BALANCE SHEET (BS)
A2: Historical actuals: the Historical Database's Quarterly tab discloses only Cash, Accounts receivable, Inventories and Accounts payable at discrete-quarter grain for all 10 historical quarters (B:K) -- shown as real literal inputs. Columns E (FY24 Q4) and I (FY25 Q4) are fiscal year-ends, so the Historical Database's Annual tab supplies a COMPLETE real 10-K balance sheet for those two columns specifically; every other historical column shows 'n/a' for line items not disclosed at quarterly grain -- never fabricated. The Q1/Q2 FY2026 Actual overlay columns (Q, Y) are treated identically: real Cash/AR/Inventory/AP only, 'n/a' elsewhere (Apple does not disclose quarterly PP&E/debt/equity detail). WHY FORECAST CASH DOES NOT RE-ANCHOR TO THESE REAL OVERLAY COLUMNS (design choice, not an oversight): a modeled 'flash close' that tried to chain the NEXT forecast quarter's PP&E/debt/Retained-Earnings roll-forward through Q or Y is mathematically impossible to balance without a hidden plug -- Q/Y carry REAL Cash/AR/Inventory/AP, but Apple does not disclose quarterly PP&E, debt, or equity detail, so any modeled PP&E/debt/equity value placed at that same column would not reconcile against the real cash/working-capital figures already sitting there (the residual would be exactly 'what cash would have had to be, had it been computed instead of real' -- a disguised plug). FIX ADOPTED: every downstream forecast column's PP&E/Term-debt/Retained-Earnings/CF-Begin-Cash roll-forward skips Q and Y and chains instead from the last fully-MODELED column of a prior vintage (T's own Q2 roll-forward prior is L, not Q; AB's own Q3 roll-forward prior is T, not Y -- see PRIOR_COL in scripts/build_bs_cf_tabs.py for the complete map) -- proved by induction to keep the balance check at exactly $0 for every scenario. CONSEQUENCE, STATED EXPLICITLY: because forecast cash rolls forward from prior MODELED cash rather than resetting to the real disclosed balance each quarter, modeled cash increasingly diverges from real reported cash as actuals come in -- e.g. in this delivered file, the live Q3 Reforecast vintage's FY2026-exit modeled cash (col AD, row 9) is ~$29.8B vs. the real FY2026 Q2 reported cash of ~$45.6B sitting two columns to the left in this same row (col K) -- a ~$15.8B / ~35% gap. This is a disclosed methodological limitation of the 'flash close' hybrid design (real revenue actuals feed the IS tab; cash/PP&E/debt/equity remain fully modeled because Apple does not disclose quarterly detail for them), not a formula error -- the balance check (row 39) still holds at $0 on every column with a full balance sheet.
A3: Forecast columns: AR/Inventory/AP are driven by Drivers!DSO_Active/DIO_Active/DPO_Active (never a rollforward plug); PP&E, non-current Term Debt, and Retained Earnings are genuine roll-forwards; Cash is pulled from the CF tab's own computed ending-cash balance (never independently plugged). Every other BS line item is held FLAT at the FY25 Q4 anchor (col I) -- documented per-item in the block starting row 41 below. 'Total' columns (P/W/AD/AJ) mirror that vintage's own Q4 column -- a balance sheet is a point-in-time stock, not a summable flow like the IS tab's Totals.
B5: =IS!B5 -> HISTORICAL ACTUALS -- Source: 02 Historical Financial Database.xlsx, Quarterly tab (real values, not re-derived) | L5: =IS!L5 -> FY2026 Approved AOP -- first rolling-forecast vintage (Drivers tab Active column; Base/Bull/Bear scenario switch at Drivers!B6) | Q5: =IS!Q5 -> Q1 FY2026 ACTUAL vs. APPROVED AOP VARIANCE -- Actual = mirror of historical col J (real data); Variance = Actual - Approved AOP Q1 (col L) | T5: =IS!T5 -> Q1 FORECAST UPDATE -- second rolling-forecast vintage (Q1 FY2026 actual reported; Q2-Q4 FY2026 reforecast using the Drivers tab Active column PLUS the Q1-actual driver adjustments in rows 63-78 below, in place of reverting to the original AOP assumptions where the Q1 variance was material) | Y5: =IS!Y5 -> Q2 FY2026 ACTUAL vs. Q1 FORECAST UPDATE VARIANCE -- Actual = mirror of historical col K (real data); Variance = Actual - Q1 Forecast Update's own Q2 column (T) | AB5: =IS!AB5 -> Q3 REFORECAST -- third rolling-forecast vintage, and the CURRENT / LIVE forecast in this project's story (Q1 and Q2 FY2026 are now both real actuals; Q3-Q4 reforecast using the Q1 Forecast Update's own Annual Build PLUS the Q2-actual driver adjustments in rows 84-99 below, in place of reverting to the Q1 Forecast Update's own assumptions where the Q2 variance was material) | AF5: =IS!AF5 -> FY2027 AOP -- fifth and FINAL rolling-forecast vintage: next year's Annual Operating Plan, built off the Q3 Reforecast's Q4 FY2026 EXIT run-rate (col AC de-seasonalized by dividing by the Q4 weight, row 12 col E -- NOT a naive x4, and NOT the Q3 Reforecast's FY26 Total), grown one more year via the Drivers tab's Active assumptions (Base/Bull/Bear switch at Drivers!B6). Fresh forward plan -- no Driver Adjustment Log (see row 125).
A6: Line Item | B6: =IS!B6 -> FY24 Q1 | C6: =IS!C6 -> FY24 Q2 | D6: =IS!D6 -> FY24 Q3 | E6: =IS!E6 -> FY24 Q4 | F6: =IS!F6 -> FY25 Q1 | G6: =IS!G6 -> FY25 Q2 | H6: =IS!H6 -> FY25 Q3 | I6: =IS!I6 -> FY25 Q4 | ... Q6: =IS!Q6 -> Q1 FY2026 Actual | T6: =IS!T6 -> Q2 -- Q1 Forecast Update | U6: =IS!U6 -> Q3 -- Q1 Forecast Update | V6: =IS!V6 -> Q4 -- Q1 Forecast Update | W6: =IS!W6 -> FY26 Total -- Q1 Forecast Update | Y6: =IS!Y6 -> Q2 FY2026 Actual | AB6: =IS!AB6 -> Q3 -- Q3 Reforecast | AC6: =IS!AC6 -> Q4 -- Q3 Reforecast | AD6: =IS!AD6 -> FY26 Total -- Q3 Reforecast | AF6: =IS!AF6 -> Q1 -- FY2027 AOP | AG6: =IS!AG6 -> Q2 -- FY2027 AOP | AH6: =IS!AH6 -> Q3 -- FY2027 AOP | AI6: =IS!AI6 -> Q4 -- FY2027 AOP | AJ6: =IS!AJ6 -> FY27 Total -- FY2027 AOP
A8: BALANCE SHEET (quarter-end / period-end)
A9: Cash and cash equivalents ($M) | B9: 40760 | C9: 32695 | D9: 25565 | E9: 29943 | F9: 30299 | G9: 28162 | H9: 36269 | I9: 35934 | J9: 45317 | K9: 45572 | L9: =CF!L30 -> 34880.118 | M9: =CF!M30 -> 32705.437 | N9: =CF!N30 -> 31259.747 | O9: =CF!O30 -> 29998.905 | P9: =O9 -> 29998.905 | Q9: =J9 -> 45317 | T9: =CF!T30 -> 32660.716 | U9: =CF!U30 -> 31112.184 | V9: =CF!V30 -> 29746.323 | W9: =V9 -> 29746.323 | Y9: =K9 -> 45572 | AB9: =CF!AB30 -> 31063.864 | AC9: =CF!AC30 -> 29784.548 | AD9: =AC9 -> 29784.548 | AF9: =CF!AF30 -> 28642.83 | AG9: =CF!AG30 -> 26306.023 | AH9: =CF!AH30 -> 24736.353 | AI9: =CF!AI30 -> 23355.631 | AJ9: =AI9 -> 23355.631
A10: Marketable securities - current ($M) | B10: n/a | C10: n/a | D10: n/a | E10: 35228 | F10: n/a | G10: n/a | H10: n/a | I10: 18763 | J10: n/a | K10: n/a | L10: =$I$10 -> 18763 | M10: =$I$10 -> 18763 | N10: =$I$10 -> 18763 | O10: =$I$10 -> 18763 | P10: =O10 -> 18763 | Q10: n/a | T10: =$I$10 -> 18763 | U10: =$I$10 -> 18763 | V10: =$I$10 -> 18763 | W10: =V10 -> 18763 | Y10: n/a | AB10: =$I$10 -> 18763 | AC10: =$I$10 -> 18763 | AD10: =AC10 -> 18763 | AF10: =$I$10 -> 18763 | AG10: =$I$10 -> 18763 | AH10: =$I$10 -> 18763 | AI10: =$I$10 -> 18763 | AJ10: =AI10 -> 18763
A11: Accounts receivable, net ($M) | B11: 23194 | C11: 21837 | D11: 22795 | E11: 33410 | F11: 29639 | G11: 26136 | H11: 27557 | I11: 39777 | J11: 39921 | K11: 30339 | L11: =DSO_Active*(IS!L41/90) -> 48801.218 | M11: =DSO_Active*(IS!M41/90) -> 37236.174 | N11: =DSO_Active*(IS!N41/90) -> 35952.169 | O11: =DSO_Active*(IS!O41/90) -> 39477.289 | P11: =O11 -> 39477.289 | Q11: =J11 -> 39921 | T11: =DSO_Active*(IS!T41/90) -> 38137.709 | U11: =DSO_Active*(IS!U41/90) -> 36822.616 | V11: =DSO_Active*(IS!V41/90) -> 40433.083 | W11: =V11 -> 40433.083 | Y11: =K11 -> 30339 | AB11: =DSO_Active*(IS!AB41/90) -> 37408.157 | AC11: =DSO_Active*(IS!AC41/90) -> 41076.037 | AD11: =AC11 -> 41076.037 | AF11: =DSO_Active*(IS!AF41/90) -> 52375.324 | AG11: =DSO_Active*(IS!AG41/90) -> 39963.28 | AH11: =DSO_Active*(IS!AH41/90) -> 38585.236 | AI11: =DSO_Active*(IS!AI41/90) -> 42368.529 | AJ11: =AI11 -> 42368.529
A12: Vendor non-trade receivables ($M) | B12: n/a | C12: n/a | D12: n/a | E12: 32833 | F12: n/a | G12: n/a | H12: n/a | I12: 33180 | J12: n/a | K12: n/a | L12: =$I$12 -> 33180 | M12: =$I$12 -> 33180 | N12: =$I$12 -> 33180 | O12: =$I$12 -> 33180 | P12: =O12 -> 33180 | Q12: n/a | T12: =$I$12 -> 33180 | U12: =$I$12 -> 33180 | V12: =$I$12 -> 33180 | W12: =V12 -> 33180 | Y12: n/a | AB12: =$I$12 -> 33180 | AC12: =$I$12 -> 33180 | AD12: =AC12 -> 33180 | AF12: =$I$12 -> 33180 | AG12: =$I$12 -> 33180 | AH12: =$I$12 -> 33180 | AI12: =$I$12 -> 33180 | AJ12: =AI12 -> 33180
A13: Inventories ($M) | B13: 6511 | C13: 6232 | D13: 6165 | E13: 7286 | F13: 6911 | G13: 6269 | H13: 5925 | I13: 5718 | J13: 5875 | K13: 6747 | L13: =DIO_Active*(IS!L43/90) -> 7723.5848 | M13: =DIO_Active*(IS!M43/90) -> 5893.229 | N13: =DIO_Active*(IS!N43/90) -> 5690.0143 | O13: =DIO_Active*(IS!O43/90) -> 6247.9217 | P13: =O13 -> 6247.9217 | Q13: =J13 -> 5875 | T13: =DIO_Active*(IS!T43/90) -> 6035.9115 | U13: =DIO_Active*(IS!U43/90) -> 5827.7767 | V13: =DIO_Active*(IS!V43/90) -> 6399.1918 | W13: =V13 -> 6399.1918 | Y13: =K13 -> 6747 | AB13: =DIO_Active*(IS!AB43/90) -> 5750.5884 | AC13: =DIO_Active*(IS!AC43/90) -> 6314.4351 | AD13: =AC13 -> 6314.4351 | AF13: =DIO_Active*(IS!AF43/90) -> 8217.0863 | AG13: =DIO_Active*(IS!AG43/90) -> 6269.7792 | AH13: =DIO_Active*(IS!AH43/90) -> 6053.58 | AI13: =DIO_Active*(IS!AI43/90) -> 6647.1351 | AJ13: =AI13 -> 6647.1351
A14: Other current assets ($M) | B14: n/a | C14: n/a | D14: n/a | E14: 14287 | F14: n/a | G14: n/a | H14: n/a | I14: 14585 | J14: n/a | K14: n/a | L14: =$I$14 -> 14585 | M14: =$I$14 -> 14585 | N14: =$I$14 -> 14585 | O14: =$I$14 -> 14585 | P14: =O14 -> 14585 | Q14: n/a | T14: =$I$14 -> 14585 | U14: =$I$14 -> 14585 | V14: =$I$14 -> 14585 | W14: =V14 -> 14585 | Y14: n/a | AB14: =$I$14 -> 14585 | AC14: =$I$14 -> 14585 | AD14: =AC14 -> 14585 | AF14: =$I$14 -> 14585 | AG14: =$I$14 -> 14585 | AH14: =$I$14 -> 14585 | AI14: =$I$14 -> 14585 | AJ14: =AI14 -> 14585
A15: Total current assets ($M) | B15: n/a | C15: n/a | D15: n/a | E15: =SUM(E9:E14) -> 152987 | F15: n/a | G15: n/a | H15: n/a | I15: =SUM(I9:I14) -> 147957 | J15: n/a | K15: n/a | L15: =SUM(L9:L14) -> 157932.92 | M15: =SUM(M9:M14) -> 142362.84 | N15: =SUM(N9:N14) -> 139429.93 | O15: =SUM(O9:O14) -> 142252.11 | P15: =O15 -> 142252.11 | Q15: n/a | T15: =SUM(T9:T14) -> 143362.34 | U15: =SUM(U9:U14) -> 140290.58 | V15: =SUM(V9:V14) -> 143106.6 | W15: =V15 -> 143106.6 | Y15: n/a | AB15: =SUM(AB9:AB14) -> 140750.61 | AC15: =SUM(AC9:AC14) -> 143703.02 | AD15: =AC15 -> 143703.02 | AF15: =SUM(AF9:AF14) -> 155763.24 | AG15: =SUM(AG9:AG14) -> 139067.08 | AH15: =SUM(AH9:AH14) -> 135903.17 | AI15: =SUM(AI9:AI14) -> 138899.29 | AJ15: =AI15 -> 138899.29
A16: Marketable securities - non-current ($M) | B16: n/a | C16: n/a | D16: n/a | E16: 91479 | F16: n/a | G16: n/a | H16: n/a | I16: 77723 | J16: n/a | K16: n/a | L16: =$I$16 -> 77723 | M16: =$I$16 -> 77723 | N16: =$I$16 -> 77723 | O16: =$I$16 -> 77723 | P16: =O16 -> 77723 | Q16: n/a | T16: =$I$16 -> 77723 | U16: =$I$16 -> 77723 | V16: =$I$16 -> 77723 | W16: =V16 -> 77723 | Y16: n/a | AB16: =$I$16 -> 77723 | AC16: =$I$16 -> 77723 | AD16: =AC16 -> 77723 | AF16: =$I$16 -> 77723 | AG16: =$I$16 -> 77723 | AH16: =$I$16 -> 77723 | AI16: =$I$16 -> 77723 | AJ16: =AI16 -> 77723
A17: Property, plant and equipment, net ($M) | B17: n/a | C17: n/a | D17: n/a | E17: 45680 | F17: n/a | G17: n/a | H17: n/a | I17: 49834 | J17: n/a | K17: n/a | L17: =I17-CF!L22-CF!L16 -> 49928.857 | M17: =L17-CF!M22-CF!M16 -> 50001.235 | N17: =M17-CF!N22-CF!N16 -> 50071.116 | O17: =N17-CF!O22-CF!O16 -> 50147.85 | P17: =O17 -> 50147.85 | Q17: n/a | T17: =L17-CF!T22-CF!T16 -> 50002.987 | U17: =T17-CF!U22-CF!U16 -> 50074.561 | V17: =U17-CF!V22-CF!V16 -> 50153.152 | W17: =V17 -> 50153.152 | Y17: n/a | AB17: =T17-CF!AB22-CF!AB16 -> 50075.699 | AC17: =AB17-CF!AC22-CF!AC16 -> 50155.54 | AD17: =AC17 -> 50155.54 | AF17: =AC17-CF!AF22-CF!AF16 -> 50257.344 | AG17: =AF17-CF!AG22-CF!AG16 -> 50335.023 | AH17: =AG17-CF!AH22-CF!AH16 -> 50410.022 | AI17: =AH17-CF!AI22-CF!AI16 -> 50492.376 | AJ17: =AI17 -> 50492.376
A18: Other non-current assets ($M) | B18: n/a | C18: n/a | D18: n/a | E18: 74834 | F18: n/a | G18: n/a | H18: n/a | I18: 83727 | J18: n/a | K18: n/a | L18: =$I$18 -> 83727 | M18: =$I$18 -> 83727 | N18: =$I$18 -> 83727 | O18: =$I$18 -> 83727 | P18: =O18 -> 83727 | Q18: n/a | T18: =$I$18 -> 83727 | U18: =$I$18 -> 83727 | V18: =$I$18 -> 83727 | W18: =V18 -> 83727 | Y18: n/a | AB18: =$I$18 -> 83727 | AC18: =$I$18 -> 83727 | AD18: =AC18 -> 83727 | AF18: =$I$18 -> 83727 | AG18: =$I$18 -> 83727 | AH18: =$I$18 -> 83727 | AI18: =$I$18 -> 83727 | AJ18: =AI18 -> 83727
A19: Total non-current assets ($M) | B19: n/a | C19: n/a | D19: n/a | E19: =SUM(E16:E18) -> 211993 | F19: n/a | G19: n/a | H19: n/a | I19: =SUM(I16:I18) -> 211284 | J19: n/a | K19: n/a | L19: =SUM(L16:L18) -> 211378.86 | M19: =SUM(M16:M18) -> 211451.23 | N19: =SUM(N16:N18) -> 211521.12 | O19: =SUM(O16:O18) -> 211597.85 | P19: =O19 -> 211597.85 | Q19: n/a | T19: =SUM(T16:T18) -> 211452.99 | U19: =SUM(U16:U18) -> 211524.56 | V19: =SUM(V16:V18) -> 211603.15 | W19: =V19 -> 211603.15 | Y19: n/a | AB19: =SUM(AB16:AB18) -> 211525.7 | AC19: =SUM(AC16:AC18) -> 211605.54 | AD19: =AC19 -> 211605.54 | AF19: =SUM(AF16:AF18) -> 211707.34 | AG19: =SUM(AG16:AG18) -> 211785.02 | AH19: =SUM(AH16:AH18) -> 211860.02 | AI19: =SUM(AI16:AI18) -> 211942.38 | AJ19: =AI19 -> 211942.38
A20: TOTAL ASSETS ($M) | B20: n/a | C20: n/a | D20: n/a | E20: =E15+E19 -> 364980 | F20: n/a | G20: n/a | H20: n/a | I20: =I15+I19 -> 359241 | J20: n/a | K20: n/a | L20: =L15+L19 -> 369311.78 | M20: =M15+M19 -> 353814.07 | N20: =N15+N19 -> 350951.05 | O20: =O15+O19 -> 353849.96 | P20: =O20 -> 353849.96 | Q20: n/a | T20: =T15+T19 -> 354815.32 | U20: =U15+U19 -> 351815.14 | V20: =V15+V19 -> 354709.75 | W20: =V20 -> 354709.75 | Y20: n/a | AB20: =AB15+AB19 -> 352276.31 | AC20: =AC15+AC19 -> 355308.56 | AD20: =AC20 -> 355308.56 | AF20: =AF15+AF19 -> 367470.58 | AG20: =AG15+AG19 -> 350852.1 | AH20: =AH15+AH19 -> 347763.19 | AI20: =AI15+AI19 -> 350841.67 | AJ20: =AI20 -> 350841.67
A22: Accounts payable ($M) | B22: 58146 | C22: 45753 | D22: 47574 | E22: 68960 | F22: 61910 | G22: 54126 | H22: 50374 | I22: 69860 | J22: 70587 | K22: 57349 | L22: =DPO_Active*(IS!L43/90) -> 88821.226 | M22: =DPO_Active*(IS!M43/90) -> 67772.134 | N22: =DPO_Active*(IS!N43/90) -> 65435.165 | O22: =DPO_Active*(IS!O43/90) -> 71851.1 | P22: =O22 -> 71851.1 | Q22: =J22 -> 70587 | T22: =DPO_Active*(IS!T43/90) -> 69412.982 | U22: =DPO_Active*(IS!U43/90) -> 67019.432 | V22: =DPO_Active*(IS!V43/90) -> 73590.705 | W22: =V22 -> 73590.705 | Y22: =K22 -> 57349 | AB22: =DPO_Active*(IS!AB43/90) -> 66131.767 | AC22: =DPO_Active*(IS!AC43/90) -> 72616.004 | AD22: =AC22 -> 72616.004 | AF22: =DPO_Active*(IS!AF43/90) -> 94496.492 | AG22: =DPO_Active*(IS!AG43/90) -> 72102.461 | AH22: =DPO_Active*(IS!AH43/90) -> 69616.17 | AI22: =DPO_Active*(IS!AI43/90) -> 76442.054 | AJ22: =AI22 -> 76442.054
A23: Other current liabilities ($M) | B23: n/a | C23: n/a | D23: n/a | E23: 78304 | F23: n/a | G23: n/a | H23: n/a | I23: 66387 | J23: n/a | K23: n/a | L23: =$I$23 -> 66387 | M23: =$I$23 -> 66387 | N23: =$I$23 -> 66387 | O23: =$I$23 -> 66387 | P23: =O23 -> 66387 | Q23: n/a | T23: =$I$23 -> 66387 | U23: =$I$23 -> 66387 | V23: =$I$23 -> 66387 | W23: =V23 -> 66387 | Y23: n/a | AB23: =$I$23 -> 66387 | AC23: =$I$23 -> 66387 | AD23: =AC23 -> 66387 | AF23: =$I$23 -> 66387 | AG23: =$I$23 -> 66387 | AH23: =$I$23 -> 66387 | AI23: =$I$23 -> 66387 | AJ23: =AI23 -> 66387
A24: Deferred revenue ($M) | B24: n/a | C24: n/a | D24: n/a | E24: 8249 | F24: n/a | G24: n/a | H24: n/a | I24: 9055 | J24: n/a | K24: n/a | L24: =$I$24 -> 9055 | M24: =$I$24 -> 9055 | N24: =$I$24 -> 9055 | O24: =$I$24 -> 9055 | P24: =O24 -> 9055 | Q24: n/a | T24: =$I$24 -> 9055 | U24: =$I$24 -> 9055 | V24: =$I$24 -> 9055 | W24: =V24 -> 9055 | Y24: n/a | AB24: =$I$24 -> 9055 | AC24: =$I$24 -> 9055 | AD24: =AC24 -> 9055 | AF24: =$I$24 -> 9055 | AG24: =$I$24 -> 9055 | AH24: =$I$24 -> 9055 | AI24: =$I$24 -> 9055 | AJ24: =AI24 -> 9055
A25: Commercial paper ($M) | B25: n/a | C25: n/a | D25: n/a | E25: 9967 | F25: n/a | G25: n/a | H25: n/a | I25: 7979 | J25: n/a | K25: n/a | L25: =$I$25 -> 7979 | M25: =$I$25 -> 7979 | N25: =$I$25 -> 7979 | O25: =$I$25 -> 7979 | P25: =O25 -> 7979 | Q25: n/a | T25: =$I$25 -> 7979 | U25: =$I$25 -> 7979 | V25: =$I$25 -> 7979 | W25: =V25 -> 7979 | Y25: n/a | AB25: =$I$25 -> 7979 | AC25: =$I$25 -> 7979 | AD25: =AC25 -> 7979 | AF25: =$I$25 -> 7979 | AG25: =$I$25 -> 7979 | AH25: =$I$25 -> 7979 | AI25: =$I$25 -> 7979 | AJ25: =AI25 -> 7979
A26: Term debt - current ($M) | B26: n/a | C26: n/a | D26: n/a | E26: 10912 | F26: n/a | G26: n/a | H26: n/a | I26: 12350 | J26: n/a | K26: n/a | L26: =$I$26 -> 12350 | M26: =$I$26 -> 12350 | N26: =$I$26 -> 12350 | O26: =$I$26 -> 12350 | P26: =O26 -> 12350 | Q26: n/a | T26: =$I$26 -> 12350 | U26: =$I$26 -> 12350 | V26: =$I$26 -> 12350 | W26: =V26 -> 12350 | Y26: n/a | AB26: =$I$26 -> 12350 | AC26: =$I$26 -> 12350 | AD26: =AC26 -> 12350 | AF26: =$I$26 -> 12350 | AG26: =$I$26 -> 12350 | AH26: =$I$26 -> 12350 | AI26: =$I$26 -> 12350 | AJ26: =AI26 -> 12350
A27: Total current liabilities ($M) | B27: n/a | C27: n/a | D27: n/a | E27: =SUM(E22:E26) -> 176392 | F27: n/a | G27: n/a | H27: n/a | I27: =SUM(I22:I26) -> 165631 | J27: n/a | K27: n/a | L27: =SUM(L22:L26) -> 184592.23 | M27: =SUM(M22:M26) -> 163543.13 | N27: =SUM(N22:N26) -> 161206.16 | O27: =SUM(O22:O26) -> 167622.1 | P27: =O27 -> 167622.1 | Q27: n/a | T27: =SUM(T22:T26) -> 165183.98 | U27: =SUM(U22:U26) -> 162790.43 | V27: =SUM(V22:V26) -> 169361.71 | W27: =V27 -> 169361.71 | Y27: n/a | AB27: =SUM(AB22:AB26) -> 161902.77 | AC27: =SUM(AC22:AC26) -> 168387 | AD27: =AC27 -> 168387 | AF27: =SUM(AF22:AF26) -> 190267.49 | AG27: =SUM(AG22:AG26) -> 167873.46 | AH27: =SUM(AH22:AH26) -> 165387.17 | AI27: =SUM(AI22:AI26) -> 172213.05 | AJ27: =AI27 -> 172213.05
A28: Term debt - non-current ($M) | B28: n/a | C28: n/a | D28: n/a | E28: 85750 | F28: n/a | G28: n/a | H28: n/a | I28: 78328 | J28: n/a | K28: n/a | L28: =I28+Debt_Roll_Active -> 78328 | M28: =L28+Debt_Roll_Active -> 78328 | N28: =M28+Debt_Roll_Active -> 78328 | O28: =N28+Debt_Roll_Active -> 78328 | P28: =O28 -> 78328 | Q28: n/a | T28: =L28+Debt_Roll_Active -> 78328 | U28: =T28+Debt_Roll_Active -> 78328 | V28: =U28+Debt_Roll_Active -> 78328 | W28: =V28 -> 78328 | Y28: n/a | AB28: =T28+Debt_Roll_Active -> 78328 | AC28: =AB28+Debt_Roll_Active -> 78328 | AD28: =AC28 -> 78328 | AF28: =AC28+Debt_Roll_Active -> 78328 | AG28: =AF28+Debt_Roll_Active -> 78328 | AH28: =AG28+Debt_Roll_Active -> 78328 | AI28: =AH28+Debt_Roll_Active -> 78328 | AJ28: =AI28 -> 78328
A29: Other non-current liabilities ($M) | B29: n/a | C29: n/a | D29: n/a | E29: 45888 | F29: n/a | G29: n/a | H29: n/a | I29: 41549 | J29: n/a | K29: n/a | L29: =$I$29 -> 41549 | M29: =$I$29 -> 41549 | N29: =$I$29 -> 41549 | O29: =$I$29 -> 41549 | P29: =O29 -> 41549 | Q29: n/a | T29: =$I$29 -> 41549 | U29: =$I$29 -> 41549 | V29: =$I$29 -> 41549 | W29: =V29 -> 41549 | Y29: n/a | AB29: =$I$29 -> 41549 | AC29: =$I$29 -> 41549 | AD29: =AC29 -> 41549 | AF29: =$I$29 -> 41549 | AG29: =$I$29 -> 41549 | AH29: =$I$29 -> 41549 | AI29: =$I$29 -> 41549 | AJ29: =AI29 -> 41549
A30: Total non-current liabilities ($M) | B30: n/a | C30: n/a | D30: n/a | E30: =SUM(E28:E29) -> 131638 | F30: n/a | G30: n/a | H30: n/a | I30: =SUM(I28:I29) -> 119877 | J30: n/a | K30: n/a | L30: =SUM(L28:L29) -> 119877 | M30: =SUM(M28:M29) -> 119877 | N30: =SUM(N28:N29) -> 119877 | O30: =SUM(O28:O29) -> 119877 | P30: =O30 -> 119877 | Q30: n/a | T30: =SUM(T28:T29) -> 119877 | U30: =SUM(U28:U29) -> 119877 | V30: =SUM(V28:V29) -> 119877 | W30: =V30 -> 119877 | Y30: n/a | AB30: =SUM(AB28:AB29) -> 119877 | AC30: =SUM(AC28:AC29) -> 119877 | AD30: =AC30 -> 119877 | AF30: =SUM(AF28:AF29) -> 119877 | AG30: =SUM(AG28:AG29) -> 119877 | AH30: =SUM(AH28:AH29) -> 119877 | AI30: =SUM(AI28:AI29) -> 119877 | AJ30: =AI30 -> 119877
A31: TOTAL LIABILITIES ($M) | B31: n/a | C31: n/a | D31: n/a | E31: =E27+E30 -> 308030 | F31: n/a | G31: n/a | H31: n/a | I31: =I27+I30 -> 285508 | J31: n/a | K31: n/a | L31: =L27+L30 -> 304469.23 | M31: =M27+M30 -> 283420.13 | N31: =N27+N30 -> 281083.16 | O31: =O27+O30 -> 287499.1 | P31: =O31 -> 287499.1 | Q31: n/a | T31: =T27+T30 -> 285060.98 | U31: =U27+U30 -> 282667.43 | V31: =V27+V30 -> 289238.71 | W31: =V31 -> 289238.71 | Y31: n/a | AB31: =AB27+AB30 -> 281779.77 | AC31: =AC27+AC30 -> 288264 | AD31: =AC31 -> 288264 | AF31: =AF27+AF30 -> 310144.49 | AG31: =AG27+AG30 -> 287750.46 | AH31: =AH27+AH30 -> 285264.17 | AI31: =AI27+AI30 -> 292090.05 | AJ31: =AI31 -> 292090.05
A33: Common stock and additional paid-in capital ($M) | B33: n/a | C33: n/a | D33: n/a | E33: 83276 | F33: n/a | G33: n/a | H33: n/a | I33: 93568 | J33: n/a | K33: n/a | L33: =$I$33 -> 93568 | M33: =$I$33 -> 93568 | N33: =$I$33 -> 93568 | O33: =$I$33 -> 93568 | P33: =O33 -> 93568 | Q33: n/a | T33: =$I$33 -> 93568 | U33: =$I$33 -> 93568 | V33: =$I$33 -> 93568 | W33: =V33 -> 93568 | Y33: n/a | AB33: =$I$33 -> 93568 | AC33: =$I$33 -> 93568 | AD33: =AC33 -> 93568 | AF33: =$I$33 -> 93568 | AG33: =$I$33 -> 93568 | AH33: =$I$33 -> 93568 | AI33: =$I$33 -> 93568 | AJ33: =AI33 -> 93568
A34: Accumulated other comprehensive income/(loss) ($M) | B34: n/a | C34: n/a | D34: n/a | E34: -7172 | F34: n/a | G34: n/a | H34: n/a | I34: -5571 | J34: n/a | K34: n/a | L34: =$I$34 -> -5571 | M34: =$I$34 -> -5571 | N34: =$I$34 -> -5571 | O34: =$I$34 -> -5571 | P34: =O34 -> -5571 | Q34: n/a | T34: =$I$34 -> -5571 | U34: =$I$34 -> -5571 | V34: =$I$34 -> -5571 | W34: =V34 -> -5571 | Y34: n/a | AB34: =$I$34 -> -5571 | AC34: =$I$34 -> -5571 | AD34: =AC34 -> -5571 | AF34: =$I$34 -> -5571 | AG34: =$I$34 -> -5571 | AH34: =$I$34 -> -5571 | AI34: =$I$34 -> -5571 | AJ34: =AI34 -> -5571
A35: Retained earnings/(Accumulated deficit) ($M) | B35: n/a | C35: n/a | D35: n/a | E35: -19154 | F35: n/a | G35: n/a | H35: n/a | I35: -14264 | J35: n/a | K35: n/a | L35: =I35+IS!L53+CF!L26+CF!L25 -> -23154.449 | M35: =L35+IS!M53+CF!M26+CF!M25 -> -17603.059 | N35: =M35+IS!N53+CF!N26+CF!N25 -> -18129.118 | O35: =N35+IS!O53+CF!O26+CF!O25 -> -21646.135 | P35: =O35 -> -21646.135 | Q35: n/a | T35: =L35+IS!T53+CF!T26+CF!T25 -> -18242.659 | U35: =T35+IS!U53+CF!U26+CF!U25 -> -18849.295 | V35: =U35+IS!V53+CF!V26+CF!V25 -> -22525.955 | W35: =V35 -> -22525.955 | Y35: n/a | AB35: =T35+IS!AB53+CF!AB26+CF!AB25 -> -17500.458 | AC35: =AB35+IS!AC53+CF!AC26+CF!AC25 -> -20952.444 | AD35: =AC35 -> -20952.444 | AF35: =AC35+IS!AF53+CF!AF26+CF!AF25 -> -30670.907 | AG35: =AF35+IS!AG53+CF!AG26+CF!AG25 -> -24895.356 | AH35: =AG35+IS!AH53+CF!AH26+CF!AH25 -> -25497.979 | AI35: =AH35+IS!AI53+CF!AI26+CF!AI25 -> -29245.383 | AJ35: =AI35 -> -29245.383
A36: TOTAL SHAREHOLDERS' EQUITY ($M) | B36: n/a | C36: n/a | D36: n/a | E36: =SUM(E33:E35) -> 56950 | F36: n/a | G36: n/a | H36: n/a | I36: =SUM(I33:I35) -> 73733 | J36: n/a | K36: n/a | L36: =SUM(L33:L35) -> 64842.551 | M36: =SUM(M33:M35) -> 70393.941 | N36: =SUM(N33:N35) -> 69867.882 | O36: =SUM(O33:O35) -> 66350.865 | P36: =O36 -> 66350.865 | Q36: n/a | T36: =SUM(T33:T35) -> 69754.341 | U36: =SUM(U33:U35) -> 69147.705 | V36: =SUM(V33:V35) -> 65471.045 | W36: =V36 -> 65471.045 | Y36: n/a | AB36: =SUM(AB33:AB35) -> 70496.542 | AC36: =SUM(AC33:AC35) -> 67044.556 | AD36: =AC36 -> 67044.556 | AF36: =SUM(AF33:AF35) -> 57326.093 | AG36: =SUM(AG33:AG35) -> 63101.644 | AH36: =SUM(AH33:AH35) -> 62499.021 | AI36: =SUM(AI33:AI35) -> 58751.617 | AJ36: =AI36 -> 58751.617
